<sdf version='1.6'>
  <world name='default'>
    <light name='sun' type='directional'>
      <cast_shadows>1</cast_shadows>
      <pose frame=''>0 0 10 0 -0 0</pose>
      <diffuse>0.8 0.8 0.8 1</diffuse>
      <specular>0.1 0.1 0.1 1</specular>
      <attenuation>
        <range>1000</range>
        <constant>0.9</constant>
        <linear>0.01</linear>
        <quadratic>0.001</quadratic>
      </attenuation>
      <direction>-0.5 0.5 -1</direction>
    </light>
    <!--<include>
       <uri>model://aruco_cube</uri>
       <name>aruco_cube1</name>
      <pose>0.3 0 0 0 0 0</pose>
    </include>-->
    <model name='ground_plane'>
      <static>1</static>
      <link name='link'>
        <collision name='collision'>
          <geometry>
            <plane>
              <normal>0 0 1</normal>
              <size>100 100</size>
            </plane>
          </geometry>
          <surface>
            <friction>
              <ode>
                <mu>100</mu>
                <mu2>50</mu2>
              </ode>
              <torsional>
                <ode/>
              </torsional>
            </friction>
            <contact>
              <ode/>
            </contact>
            <bounce/>
          </surface>
          <max_contacts>10</max_contacts>
        </collision>
        <visual name='visual'>
          <cast_shadows>0</cast_shadows>
          <geometry>
            <plane>
              <normal>0 0 1</normal>
              <size>100 100</size>
            </plane>
          </geometry>
          <material>
            <script>
              <uri>file://media/materials/scripts/gazebo.material</uri>
              <name>Gazebo/Grey</name>
            </script>
          </material>
        </visual>
        <self_collide>0</self_collide>
        <kinematic>0</kinematic>
        <gravity>1</gravity>
      </link>
    </model>
    <gravity>0 0 -9.8</gravity>
    <magnetic_field>6e-06 2.3e-05 -4.2e-05</magnetic_field>
    <atmosphere type='adiabatic'/>
    <physics name='default_physics' default='0' type='ode'>
      <max_step_size>0.001</max_step_size>
      <real_time_factor>1</real_time_factor>
      <real_time_update_rate>1000</real_time_update_rate>
    </physics>
    <scene>
      <ambient>0.4 0.4 0.4 1</ambient>
      <background>0.7 0.7 0.7 1</background>
      <shadows>1</shadows>
    </scene>
    <spherical_coordinates>
      <surface_model>EARTH_WGS84</surface_model>
      <latitude_deg>0</latitude_deg>
      <longitude_deg>0</longitude_deg>
      <elevation>0</elevation>
      <heading_deg>0</heading_deg>
    </spherical_coordinates>
    <model name='seven_dof_arm'>
      <link name='base_link'>
        <pose frame=''>0 0 0 0 -0 0</pose>
        <inertial>
          <pose frame=''>0.026613 0.000111 0.148274 0 -0 0</pose>
          <mass>1.2247</mass>
          <inertia>
            <ixx>1.11989</ixx>
            <ixy>-1.6741e-05</ixy>
            <ixz>-0.0215074</ixz>
            <iyy>0.623738</iyy>
            <iyz>-8.81946e-05</iyz>
            <izz>1.00392</izz>
          </inertia>
        </inertial>
        <collision name='base_link_collision'>
          <pose frame=''>0 0 0 1.57079 -0 0</pose>
          <geometry>
            <box>
              <size>0.1 0.1 0.1</size>
            </box>
          </geometry>
          <surface>
            <contact>
              <ode/>
            </contact>
            <friction>
              <ode/>
              <torsional>
                <ode/>
              </torsional>
            </friction>
            <bounce/>
          </surface>
          <max_contacts>10</max_contacts>
        </collision>
        <collision name='base_link_fixed_joint_lump__bottom_link_collision_1'>
          <pose frame=''>0 0 -0.04 0 -0 0</pose>
          <geometry>
            <box>
              <size>1 1 0.02</size>
            </box>
          </geometry>
          <surface>
            <contact>
              <ode/>
            </contact>
            <friction>
              <ode/>
              <torsional>
                <ode/>
              </torsional>
            </friction>
            <bounce/>
          </surface>
          <max_contacts>10</max_contacts>
        </collision>
        <visual name='base_link_visual'>
          <pose frame=''>0 0 0 1.57079 -0 0</pose>
          <geometry>
            <box>
              <size>0.1 0.1 0.1</size>
            </box>
          </geometry>
          <material>
            <script>
              <name>Gazebo/White</name>
              <uri>file://media/materials/scripts/gazebo.material</uri>
            </script>
          </material>
        </visual>
        <visual name='base_link_fixed_joint_lump__bottom_link_visual_1'>
          <pose frame=''>0 0 -0.04 0 -0 0</pose>
          <geometry>
            <box>
              <size>1 1 0.02</size>
            </box>
          </geometry>
          <material>
            <script>
              <name>Gazebo/White</name>
              <uri>file://media/materials/scripts/gazebo.material</uri>
            </script>
          </material>
        </visual>
        <visual name='base_link_fixed_joint_lump__rgbd_camera_link_visual_2'>
          <pose frame=''>0.15 0 0.8 0 1.309 0</pose>
          <geometry>
            <mesh>
              <scale>1 1 1</scale>
              <uri>/home/jan/catkin_ws/src/mastering_ros_robot_description_pkg/meshes/sensors/xtion_pro_live/xtion_pro_live.dae</uri>
            </mesh>
          </geometry>
          <material>
            <script>
              <uri>__default__</uri>
              <name>__default__</name>
            </script>
          </material>
        </visual>
        <velocity_decay/>
        <velocity_decay/>
        <gravity>1</gravity>
        <velocity_decay/>
        <self_collide>0</self_collide>
        <sensor name='rgbd_camera_frame_sensor' type='depth'>
          <always_on>1</always_on>
          <update_rate>6</update_rate>
          <camera name='__default__'>
            <horizontal_fov>1.01229</horizontal_fov>
            <image>
              <format>R8G8B8</format>
              <width>800</width>
              <height>600</height>
            </image>
            <clip>
              <near>0.05</near>
              <far>1.5</far>
            </clip>
          </camera>
	  <plugin name="camera_plugin" filename="libgazebo_ros_openni_kinect.so">
	   <baseline>0.2</baseline>
	   <alwaysOn>true</alwaysOn>
 	   <!-- Keep this zero, update_rate in the parent <sensor> tag
	       will control the frame rate. -->
	   <updateRate>20.0</updateRate>
	   <cameraName>camera_ir</cameraName>
	   <imageTopicName>/camera/color/image_raw</imageTopicName>
	   <cameraInfoTopicName>/camera/color/camera_info</cameraInfoTopicName>
	   <depthImageTopicName>/camera/depth/image_raw</depthImageTopicName>
	   <depthImageCameraInfoTopicName>/camera/depth/camera_info</depthImageCameraInfoTopicName>
	   <pointCloudTopicName>/camera/depth/points</pointCloudTopicName>
	   <frameName>depth_camera_link</frameName>
	   <pointCloudCutoff>0.05</pointCloudCutoff>
	   <distortionK1>0</distortionK1>
 	   <distortionK2>0</distortionK2>
	   <distortionK3>0</distortionK3>
	   <distortionT1>0</distortionT1>
	   <distortionT2>0</distortionT2>
	   <CxPrime>0</CxPrime>
	   <Cx>0</Cx>
	   <Cy>0</Cy>
	   <focalLength>0</focalLength>
	   <hackBaseline>0</hackBaseline>
	 </plugin>
          <pose frame=''>0.15 0 0.8 0 1.309 0</pose>
        </sensor>
        <sensor name='rgbd_camera_frame_sensor' type='depth'>
          <always_on>1</always_on>
          <update_rate>6</update_rate>
          <camera name='__default__'>
            <horizontal_fov>1.01229</horizontal_fov>
            <image>
              <format>R8G8B8</format>
              <width>800</width>
              <height>600</height>
            </image>
            <clip>
              <near>0.05</near>
              <far>1.5</far>
            </clip>
          </camera>
          <plugin name='rgbd_camera_frame_controller' filename='libgazebo_ros_openni_kinect.so'>
            <alwaysOn>true</alwaysOn>
            <updateRate>6.0</updateRate>
            <cameraName>rgbd_camera</cameraName>
            <imageTopicName>rgb/image_raw</imageTopicName>
            <cameraInfoTopicName>rgb/camera_info</cameraInfoTopicName>
            <pointCloudTopicName>rgb/points</pointCloudTopicName>
            <depthImageTopicName>depth/image_raw</depthImageTopicName>
            <depthImageCameraInfoTopicName>depth/camera_info</depthImageCameraInfoTopicName>
            <frameName>rgbd_camera_optical_frame</frameName>
            <pointCloudCutoff>0.05</pointCloudCutoff>
            <pointCloudCutoffMax>5</pointCloudCutoffMax>
            <rangeMax>1.5</rangeMax>
            <robotNamespace>/</robotNamespace>
          </plugin>
          <pose frame=''>0.15 0 0.8 0 1.309 0</pose>
        </sensor>
        <kinematic>0</kinematic>
      </link>
      <link name='shoulder_pan_link'>
        <pose frame=''>0 0 0.05 3.14159 1.57079 3.14159</pose>
        <inertial>
          <pose frame=''>0 0 0 0 -0 0</pose>
          <mass>1</mass>
          <inertia>
            <ixx>1</ixx>
            <ixy>0</ixy>
            <ixz>0</ixz>
            <iyy>0.5</iyy>
            <iyz>0</iyz>
            <izz>1</izz>
          </inertia>
        </inertial>
        <collision name='shoulder_pan_link_collision'>
          <pose frame=''>0 0 0 3.14159 1.57079 3.14159</pose>
          <geometry>
            <cylinder>
              <length>0.08</length>
              <radius>0.04</radius>
            </cylinder>
          </geometry>
          <surface>
            <contact>
              <ode/>
            </contact>
            <friction>
              <ode/>
              <torsional>
                <ode/>
              </torsional>
            </friction>
            <bounce/>
          </surface>
          <max_contacts>10</max_contacts>
        </collision>
        <visual name='shoulder_pan_link_visual'>
          <pose frame=''>0 0 0 3.14159 1.57079 3.14159</pose>
          <geometry>
            <cylinder>
              <length>0.08</length>
              <radius>0.04</radius>
            </cylinder>
          </geometry>
          <material>
            <script>
              <name>Gazebo/Red</name>
              <uri>file://media/materials/scripts/gazebo.material</uri>
            </script>
          </material>
        </visual>
        <gravity>1</gravity>
        <velocity_decay/>
        <self_collide>0</self_collide>
        <kinematic>0</kinematic>
      </link>
      <joint name='shoulder_pan_joint' type='revolute'>
        <child>shoulder_pan_link</child>
        <parent>base_link</parent>
        <axis>
          <xyz>-1e-06 0 1</xyz>
          <limit>
            <lower>-2.61799</lower>
            <upper>1.98395</upper>
            <effort>300</effort>
            <velocity>1</velocity>
          </limit>
          <dynamics>
            <damping>50</damping>
            <friction>1</friction>
            <spring_reference>0</spring_reference>
            <spring_stiffness>0</spring_stiffness>
          </dynamics>
          <use_parent_model_frame>1</use_parent_model_frame>
        </axis>
      </joint>
      <link name='shoulder_pitch_link'>
        <pose frame=''>-0 0.0021 0.091 0 1e-06 1.5708</pose>
        <inertial>
          <pose frame=''>0 0 0 0 -0 0</pose>
          <mass>1</mass>
          <inertia>
            <ixx>1</ixx>
            <ixy>0</ixy>
            <ixz>0</ixz>
            <iyy>0.5</iyy>
            <iyz>0</iyz>
            <izz>1</izz>
          </inertia>
        </inertial>
        <collision name='shoulder_pitch_link_collision'>
          <pose frame=''>-0.002 0 0.04 3.14159 1.57079 3.14159</pose>
          <geometry>
            <box>
              <size>0.14 0.04 0.04</size>
            </box>
          </geometry>
          <surface>
            <contact>
              <ode/>
            </contact>
            <friction>
              <ode/>
              <torsional>
                <ode/>
              </torsional>
            </friction>
            <bounce/>
          </surface>
          <max_contacts>10</max_contacts>
        </collision>
        <visual name='shoulder_pitch_link_visual'>
          <pose frame=''>-0.002 0 0.04 3.14159 1.57079 3.14159</pose>
          <geometry>
            <box>
              <size>0.14 0.04 0.04</size>
            </box>
          </geometry>
          <material>
            <script>
              <name>Gazebo/White</name>
              <uri>file://media/materials/scripts/gazebo.material</uri>
            </script>
          </material>
        </visual>
        <gravity>1</gravity>
        <velocity_decay/>
        <self_collide>0</self_collide>
        <kinematic>0</kinematic>
      </link>
      <joint name='shoulder_pitch_joint' type='revolute'>
        <child>shoulder_pitch_link</child>
        <parent>shoulder_pan_link</parent>
        <axis>
          <xyz>0 1 -1e-06</xyz>
          <limit>
            <lower>-1.19963</lower>
            <upper>1.89994</upper>
            <effort>300</effort>
            <velocity>1</velocity>
          </limit>
          <dynamics>
            <damping>50</damping>
            <friction>1</friction>
            <spring_reference>0</spring_reference>
            <spring_stiffness>0</spring_stiffness>
          </dynamics>
          <use_parent_model_frame>1</use_parent_model_frame>
        </axis>
      </joint>
      <link name='elbow_roll_link'>
        <pose frame=''>-0 0.0001 0.2116 -0.785403 1.57079 -1.57079</pose>
        <inertial>
          <pose frame=''>0 0 0 0 -0 0</pose>
          <mass>1</mass>
          <inertia>
            <ixx>1</ixx>
            <ixy>0</ixy>
            <ixz>0</ixz>
            <iyy>0.5</iyy>
            <iyz>0</iyz>
            <izz>1</izz>
          </inertia>
        </inertial>
        <collision name='elbow_roll_link_collision'>
          <pose frame=''>-0.015 0 -0 3.14159 1.57079 3.14159</pose>
          <geometry>
            <cylinder>
              <length>0.06</length>
              <radius>0.02</radius>
            </cylinder>
          </geometry>
          <surface>
            <contact>
              <ode/>
            </contact>
            <friction>
              <ode/>
              <torsional>
                <ode/>
              </torsional>
            </friction>
            <bounce/>
          </surface>
          <max_contacts>10</max_contacts>
        </collision>
        <visual name='elbow_roll_link_visual'>
          <pose frame=''>-0.015 0 -0 3.14159 1.57079 3.14159</pose>
          <geometry>
            <cylinder>
              <length>0.06</length>
              <radius>0.02</radius>
            </cylinder>
          </geometry>
          <material>
            <script>
              <name>Gazebo/Black</name>
              <uri>file://media/materials/scripts/gazebo.material</uri>
            </script>
          </material>
        </visual>
        <gravity>1</gravity>
        <velocity_decay/>
        <self_collide>0</self_collide>
        <kinematic>0</kinematic>
      </link>
      <joint name='elbow_roll_joint' type='revolute'>
        <child>elbow_roll_link</child>
        <parent>shoulder_pitch_link</parent>
        <axis>
          <xyz>0 0 1</xyz>
          <limit>
            <lower>-2.61799</lower>
            <upper>0.705631</upper>
            <effort>300</effort>
            <velocity>1</velocity>
          </limit>
          <dynamics>
            <damping>50</damping>
            <friction>1</friction>
            <spring_reference>0</spring_reference>
            <spring_stiffness>0</spring_stiffness>
          </dynamics>
          <use_parent_model_frame>1</use_parent_model_frame>
        </axis>
      </joint>
      <link name='elbow_pitch_link'>
        <pose frame=''>-0 0.0001 0.2466 -3.08659 1e-06 1.5708</pose>
        <inertial>
          <pose frame=''>0 0 0 0 -0 0</pose>
          <mass>1</mass>
          <inertia>
            <ixx>1</ixx>
            <ixy>0</ixy>
            <ixz>0</ixz>
            <iyy>0.5</iyy>
            <iyz>0</iyz>
            <izz>1</izz>
          </inertia>
        </inertial>
        <collision name='elbow_pitch_link_collision'>
          <pose frame=''>0 0 -0.12 3.14159 1.57079 3.14159</pose>
          <geometry>
            <box>
              <size>0.22 0.04 0.04</size>
            </box>
          </geometry>
          <surface>
            <contact>
              <ode/>
            </contact>
            <friction>
              <ode/>
              <torsional>
                <ode/>
              </torsional>
            </friction>
            <bounce/>
          </surface>
          <max_contacts>10</max_contacts>
        </collision>
        <visual name='elbow_pitch_link_visual'>
          <pose frame=''>0 0 -0.12 3.14159 1.57079 3.14159</pose>
          <geometry>
            <box>
              <size>0.22 0.04 0.04</size>
            </box>
          </geometry>
          <material>
            <script>
              <name>Gazebo/Red</name>
              <uri>file://media/materials/scripts/gazebo.material</uri>
            </script>
          </material>
        </visual>
        <gravity>1</gravity>
        <velocity_decay/>
        <self_collide>0</self_collide>
        <kinematic>0</kinematic>
      </link>
      <joint name='elbow_pitch_joint' type='revolute'>
        <child>elbow_pitch_link</child>
        <parent>elbow_roll_link</parent>
        <axis>
          <xyz>-3e-06 1 -1e-06</xyz>
          <limit>
            <lower>-1.59534</lower>
            <upper>1.93282</upper>
            <effort>300</effort>
            <velocity>1</velocity>
          </limit>
          <dynamics>
            <damping>50</damping>
            <friction>1</friction>
            <spring_reference>0</spring_reference>
            <spring_stiffness>0</spring_stiffness>
          </dynamics>
          <use_parent_model_frame>1</use_parent_model_frame>
        </axis>
      </joint>
      <link name='wrist_roll_link'>
        <pose frame=''>0.021721 0.000101 0.49378 1.5708 -1.5158 3e-06</pose>
        <inertial>
          <pose frame=''>0 0 0 0 -0 0</pose>
          <mass>1</mass>
          <inertia>
            <ixx>1</ixx>
            <ixy>0</ixy>
            <ixz>0</ixz>
            <iyy>0.5</iyy>
            <iyz>0</iyz>
            <izz>1</izz>
          </inertia>
        </inertial>
        <collision name='wrist_roll_link_collision'>
          <pose frame=''>0 0 0 3.14159 1.57079 3.14159</pose>
          <geometry>
            <cylinder>
              <length>0.06</length>
              <radius>0.02</radius>
            </cylinder>
          </geometry>
          <surface>
            <contact>
              <ode/>
            </contact>
            <friction>
              <ode/>
              <torsional>
                <ode/>
              </torsional>
            </friction>
            <bounce/>
          </surface>
          <max_contacts>10</max_contacts>
        </collision>
        <visual name='wrist_roll_link_visual'>
          <pose frame=''>0 0 0 3.14159 1.57079 3.14159</pose>
          <geometry>
            <cylinder>
              <length>0.06</length>
              <radius>0.02</radius>
            </cylinder>
          </geometry>
          <material>
            <script>
              <name>Gazebo/Black</name>
              <uri>file://media/materials/scripts/gazebo.material</uri>
            </script>
          </material>
        </visual>
        <gravity>1</gravity>
        <velocity_decay/>
        <self_collide>0</self_collide>
        <kinematic>0</kinematic>
      </link>
      <joint name='wrist_roll_joint' type='revolute'>
        <child>wrist_roll_link</child>
        <parent>elbow_pitch_link</parent>
        <axis>
          <xyz>0.054972 0 0.998488</xyz>
          <limit>
            <lower>-2.61799</lower>
            <upper>2.61288</upper>
            <effort>300</effort>
            <velocity>1</velocity>
          </limit>
          <dynamics>
            <damping>50</damping>
            <friction>1</friction>
            <spring_reference>0</spring_reference>
            <spring_stiffness>0</spring_stiffness>
          </dynamics>
          <use_parent_model_frame>1</use_parent_model_frame>
        </axis>
      </joint>
      <link name='wrist_pitch_link'>
        <pose frame=''>0.021721 1e-06 0.49378 0.055 -1e-06 1.5708</pose>
        <inertial>
          <pose frame=''>0 0 0 0 -0 0</pose>
          <mass>1</mass>
          <inertia>
            <ixx>1</ixx>
            <ixy>0</ixy>
            <ixz>0</ixz>
            <iyy>0.5</iyy>
            <iyz>0</iyz>
            <izz>1</izz>
          </inertia>
        </inertial>
        <collision name='wrist_pitch_link_collision'>
          <pose frame=''>0 0 0.04 3.14159 1.57079 3.14159</pose>
          <geometry>
            <box>
              <size>0.06 0.04 0.04</size>
            </box>
          </geometry>
          <surface>
            <contact>
              <ode/>
            </contact>
            <friction>
              <ode/>
              <torsional>
                <ode/>
              </torsional>
            </friction>
            <bounce/>
          </surface>
          <max_contacts>10</max_contacts>
        </collision>
        <visual name='wrist_pitch_link_visual'>
          <pose frame=''>0 0 0.04 3.14159 1.57079 3.14159</pose>
          <geometry>
            <box>
              <size>0.06 0.04 0.04</size>
            </box>
          </geometry>
          <material>
            <script>
              <name>Gazebo/White</name>
              <uri>file://media/materials/scripts/gazebo.material</uri>
            </script>
          </material>
        </visual>
        <gravity>1</gravity>
        <velocity_decay/>
        <self_collide>0</self_collide>
        <kinematic>0</kinematic>
      </link>
      <joint name='wrist_pitch_joint' type='revolute'>
        <child>wrist_pitch_link</child>
        <parent>wrist_roll_link</parent>
        <axis>
          <xyz>-5e-06 1 1e-06</xyz>
          <limit>
            <lower>-1.59534</lower>
            <upper>1.98395</upper>
            <effort>300</effort>
            <velocity>1</velocity>
          </limit>
          <dynamics>
            <damping>50</damping>
            <friction>1</friction>
            <spring_reference>0</spring_reference>
            <spring_stiffness>0</spring_stiffness>
          </dynamics>
          <use_parent_model_frame>1</use_parent_model_frame>
        </axis>
      </joint>
      <link name='gripper_roll_link'>
        <pose frame=''>0.026119 0 0.573659 -1e-06 -1.5158 3e-06</pose>
        <inertial>
          <pose frame=''>0 0 0 0 -0 0</pose>
          <mass>1</mass>
          <inertia>
            <ixx>1</ixx>
            <ixy>0</ixy>
            <ixz>0</ixz>
            <iyy>0.5</iyy>
            <iyz>0</iyz>
            <izz>1</izz>
          </inertia>
        </inertial>
        <collision name='gripper_roll_link_collision'>
          <pose frame=''>0 0 0 3.14159 1.57079 3.14159</pose>
          <geometry>
            <cylinder>
              <length>0.02</length>
              <radius>0.04</radius>
            </cylinder>
          </geometry>
          <surface>
            <contact>
              <ode/>
            </contact>
            <friction>
              <ode/>
              <torsional>
                <ode/>
              </torsional>
            </friction>
            <bounce/>
          </surface>
          <max_contacts>10</max_contacts>
        </collision>
        <visual name='gripper_roll_link_visual'>
          <pose frame=''>0 0 0 3.14159 1.57079 3.14159</pose>
          <geometry>
            <cylinder>
              <length>0.02</length>
              <radius>0.04</radius>
            </cylinder>
          </geometry>
          <material>
            <script>
              <name>Gazebo/Red</name>
              <uri>file://media/materials/scripts/gazebo.material</uri>
            </script>
          </material>
        </visual>
        <gravity>1</gravity>
        <velocity_decay/>
        <self_collide>0</self_collide>
        <kinematic>0</kinematic>
      </link>
      <joint name='gripper_roll_joint' type='revolute'>
        <child>gripper_roll_link</child>
        <parent>wrist_pitch_link</parent>
        <axis>
          <xyz>0.054972 0 0.998488</xyz>
          <limit>
            <lower>-2.61799</lower>
            <upper>2.61288</upper>
            <effort>300</effort>
            <velocity>1</velocity>
          </limit>
          <dynamics>
            <damping>50</damping>
            <friction>1</friction>
            <spring_reference>0</spring_reference>
            <spring_stiffness>0</spring_stiffness>
          </dynamics>
          <use_parent_model_frame>1</use_parent_model_frame>
        </axis>
      </joint>
      <link name='gripper_finger_link1'>
        <pose frame=''>0.026119 0 0.573659 -1e-06 -1.5158 3e-06</pose>
        <inertial>
          <pose frame=''>0 0 0 0 -0 0</pose>
          <mass>1</mass>
          <inertia>
            <ixx>1</ixx>
            <ixy>0</ixy>
            <ixz>0</ixz>
            <iyy>0.5</iyy>
            <iyz>0</iyz>
            <izz>1</izz>
          </inertia>
        </inertial>
        <visual name='gripper_finger_link1_visual'>
          <pose frame=''>0.04 -0.03 0 0 -0 0</pose>
          <geometry>
            <box>
              <size>0.08 0.01 0.01</size>
            </box>
          </geometry>
        </visual>
        <self_collide>0</self_collide>
        <kinematic>0</kinematic>
        <gravity>1</gravity>
      </link>
      <joint name='finger_joint1' type='prismatic'>
        <child>gripper_finger_link1</child>
        <parent>gripper_roll_link</parent>
        <axis>
          <xyz>-1e-06 1 -0</xyz>
          <limit>
            <lower>0</lower>
            <upper>0.03</upper>
            <effort>100</effort>
            <velocity>1</velocity>
          </limit>
          <dynamics>
            <damping>50</damping>
            <friction>1</friction>
            <spring_reference>0</spring_reference>
            <spring_stiffness>0</spring_stiffness>
          </dynamics>
          <use_parent_model_frame>1</use_parent_model_frame>
        </axis>
      </joint>
      <link name='gripper_finger_link2'>
        <pose frame=''>0.026119 0 0.573659 -1e-06 -1.5158 3e-06</pose>
        <inertial>
          <pose frame=''>0 0 0 0 -0 0</pose>
          <mass>1</mass>
          <inertia>
            <ixx>1</ixx>
            <ixy>0</ixy>
            <ixz>0</ixz>
            <iyy>0.5</iyy>
            <iyz>0</iyz>
            <izz>1</izz>
          </inertia>
        </inertial>
        <visual name='gripper_finger_link2_visual'>
          <pose frame=''>0.04 0.03 0 0 -0 0</pose>
          <geometry>
            <box>
              <size>0.08 0.01 0.01</size>
            </box>
          </geometry>
        </visual>
        <self_collide>0</self_collide>
        <kinematic>0</kinematic>
        <gravity>1</gravity>
      </link>
      <joint name='finger_joint2' type='prismatic'>
        <child>gripper_finger_link2</child>
        <parent>gripper_roll_link</parent>
        <axis>
          <xyz>-1e-06 1 -0</xyz>
          <limit>
            <lower>-0.03</lower>
            <upper>0</upper>
            <effort>1</effort>
            <velocity>1</velocity>
          </limit>
          <dynamics>
            <damping>50</damping>
            <friction>1</friction>
            <spring_reference>0</spring_reference>
            <spring_stiffness>0</spring_stiffness>
          </dynamics>
          <use_parent_model_frame>1</use_parent_model_frame>
        </axis>
      </joint>
      <static>0</static>
      <plugin name='gazebo_ros_control' filename='libgazebo_ros_control.so'>
        <robotNamespace>/seven_dof_arm</robotNamespace>
      </plugin>
      <pose frame=''>0 0 0 0 -0 0</pose>
    </model>
    <model name='aruco_cube'>
      <static>0</static>
      <link name='link'>
        <inertial>
          <mass>0.05</mass>
          <inertia>
            <ixx>5.2083e-05</ixx>
            <ixy>0</ixy>
            <ixz>0</ixz>
            <iyy>5.2083e-05</iyy>
            <iyz>0</iyz>
            <izz>2.0833e-05</izz>
          </inertia>
        </inertial>
        <collision name='colision'>
          <pose frame=''>0 0 0 0 -0 0</pose>
          <geometry>
            <box>
              <size>0.05 0.05 0.1</size>
            </box>
          </geometry>
          <surface>
            <friction>
              <ode>
                <mu>30</mu>
                <mu2>30</mu2>
                <fdir1>0 0 0</fdir1>
              </ode>
              <torsional>
                <ode/>
              </torsional>
            </friction>
            <contact>
              <ode>
                <kp>1e+06</kp>
                <kd>100</kd>
                <min_depth>0.0025</min_depth>
                <max_vel>1</max_vel>
              </ode>
            </contact>
            <bounce/>
          </surface>
          <max_contacts>10</max_contacts>
        </collision>
        <visual name='visual1'>
          <pose frame=''>0 0 0 0 -0 0</pose>
          <geometry>
            <mesh>
              <uri>model://aruco_cube/meshes/aruco_cube_5cm.dae</uri>
              <scale>1 1 1</scale>
            </mesh>
          </geometry>
        </visual>
        <velocity_decay>
          <linear>0</linear>
          <angular>0</angular>
        </velocity_decay>
        <self_collide>0</self_collide>
        <kinematic>0</kinematic>
        <gravity>1</gravity>
      </link>
      <pose frame=''>0.632399 0.007837 0 0 -0 0</pose>
    </model>
    <state world_name='default'>
      <sim_time>283 173000000</sim_time>
      <real_time>285 133308904</real_time>
      <wall_time>1525413281 631127688</wall_time>
      <iterations>283173</iterations>
      <model name='aruco_cube'>
        <pose frame=''>0.300543 0.007833 0.07 1e-06 -0 -2.7e-05</pose>
        <scale>1 1 1</scale>
        <link name='link'>
          <pose frame=''>0.300543 0.007833 0.07 1e-06 -0 -2.7e-05</pose>
          <velocity>2.3e-05 9e-06 0.008702 -0.000106 0.00038 -0</velocity>
          <acceleration>0.023325 0.009384 8.70243 -0.105879 0.379874 -0.000166</acceleration>
          <wrench>0.001166 0.000469 0.435122 0 -0 0</wrench>
        </link>
      </model>
      <model name='ground_plane'>
        <pose frame=''>0 0 0 0 -0 0</pose>
        <scale>1 1 1</scale>
        <link name='link'>
          <pose frame=''>0 0 0 0 -0 0</pose>
          <velocity>0 0 0 0 -0 0</velocity>
          <acceleration>0 0 0 0 -0 0</acceleration>
          <wrench>0 0 0 0 -0 0</wrench>
        </link>
      </model>
      <model name='seven_dof_arm'>
        <pose frame=''>-0.007648 6e-06 0.050001 1e-06 -0 -0.000239</pose>
        <scale>1 1 1</scale>
        <link name='base_link'>
          <pose frame=''>-0.007648 6e-06 0.050001 1e-06 -0 -0.000239</pose>
          <velocity>1.1e-05 1e-05 0.009475 -0.000208 0.000214 0</velocity>
          <acceleration>0.040606 0.067833 18.9654 -0.353668 0.247039 0.000378</acceleration>
          <wrench>0.04973 0.083075 23.2269 0 -0 0</wrench>
        </link>
        <link name='elbow_pitch_link'>
          <pose frame=''>-0.007648 0.000106 0.296597 -3.08659 -1e-06 1.57056</pose>
          <velocity>9.4e-05 0 0.008683 -7.9e-05 0.000383 7e-06</velocity>
          <acceleration>0.094043 0.000499 8.68291 -0.159148 0.191763 0.011031</acceleration>
          <wrench>0.094043 0.000499 8.68291 0 -0 0</wrench>
        </link>
        <link name='elbow_roll_link'>
          <pose frame=''>-0.007648 0.000106 0.261598 -0.813685 1.57079 -1.59931</pose>
          <velocity>8e-05 7e-06 0.008896 -0.000109 0.000304 6e-06</velocity>
          <acceleration>0.079556 0.007345 8.89613 -0.087384 0.173234 0.005946</acceleration>
          <wrench>0.079556 0.007345 8.89613 0 -0 0</wrench>
        </link>
        <link name='gripper_finger_link1'>
          <pose frame=''>0.018471 0 0.623652 4e-05 -1.5158 -0.000277</pose>
          <velocity>0.000241 -2.5e-05 0.007933 3.4e-05 0.000456 7e-06</velocity>
          <acceleration>0.240821 -0.024621 7.93276 0.033577 0.45606 0.007244</acceleration>
          <wrench>0.240821 -0.024621 7.93276 0 -0 0</wrench>
        </link>
        <link name='gripper_finger_link2'>
          <pose frame=''>0.018471 0 0.623652 3.9e-05 -1.5158 -0.000277</pose>
          <velocity>0.000239 -0.000299 0.008005 2.8e-05 0.000449 7e-06</velocity>
          <acceleration>0.239232 -0.29941 8.00515 0.027971 0.449065 0.007172</acceleration>
          <wrench>0.239232 -0.29941 8.00515 0 -0 0</wrench>
        </link>
        <link name='gripper_roll_link'>
          <pose frame=''>0.018471 -1e-06 0.623653 3.8e-05 -1.5158 -0.000276</pose>
          <velocity>0.000237 -1e-05 0.008108 1.9e-05 0.000439 7e-06</velocity>
          <acceleration>0.236587 -0.009861 8.10822 0.019184 0.438831 0.007017</acceleration>
          <wrench>0.236587 -0.009861 8.10822 0 -0 0</wrench>
        </link>
        <link name='shoulder_pan_link'>
          <pose frame=''>-0.007648 6e-06 0.1 2.98127 1.57079 2.98103</pose>
          <velocity>2.6e-05 2e-06 0.009324 -0.000184 0.00023 4e-06</velocity>
          <acceleration>0.026322 0.002474 9.32414 -0.183572 0.22988 0.003807</acceleration>
          <wrench>0.026322 0.002474 9.32414 0 -0 0</wrench>
        </link>
        <link name='shoulder_pitch_link'>
          <pose frame=''>-0.007647 0.002106 0.140999 0 -0 1.57056</pose>
          <velocity>3.9e-05 -1e-06 0.009111 -0.000164 0.000301 5e-06</velocity>
          <acceleration>0.039264 -0.000841 9.11149 -0.32825 0.150709 0.004776</acceleration>
          <wrench>0.039264 -0.000841 9.11149 0 -0 0</wrench>
        </link>
        <link name='wrist_pitch_link'>
          <pose frame=''>0.014073 1e-06 0.543775 0.055 -3e-06 1.57056</pose>
          <velocity>0.000198 -2e-06 0.00828 -1.1e-05 0.000428 7e-06</velocity>
          <acceleration>0.198295 -0.002179 8.27953 -0.021681 0.214102 0.007201</acceleration>
          <wrench>0.198295 -0.002179 8.27953 0 -0 0</wrench>
        </link>
        <link name='wrist_roll_link'>
          <pose frame=''>0.014073 0.000101 0.543776 1.57083 -1.5158 -0.00027</pose>
          <velocity>0.000194 7e-06 0.00847 -3.9e-05 0.000409 7e-06</velocity>
          <acceleration>0.194073 0.007466 8.46963 -0.079167 0.204738 0.009474</acceleration>
          <wrench>0.194073 0.007466 8.46963 0 -0 0</wrench>
        </link>
      </model>
      <light name='sun'>
        <pose frame=''>0 0 10 0 -0 0</pose>
      </light>
    </state>
    <gui fullscreen='0'>
      <camera name='user_camera'>
        <pose frame=''>5.00365 -4.99635 2 0 0.275643 2.35619</pose>
        <view_controller>orbit</view_controller>
        <projection_type>perspective</projection_type>
      </camera>
    </gui>
  </world>
</sdf>
